---
layout: post
title: Go语言错误处理和资源管理
category : go
tags : [go]
stickie: true
date: 2019-6-22 00:00:00
---

# 0x01 defer

确保调用在函数结束时发生

```go
func tryDefer() {
	defer fmt.Println(1)
	defer fmt.Println(2)
}
```

上面的代码输出结果是`2 1`，我们可以将`defer`后的语句看成在做压栈操作。当函数调用结束的时候，我们可以将`defer`的结果做出栈操作。

# 0x02 出错返回和封装

```go
func HandleFileList(writer http.ResponseWriter, request *http.Request) error {
	path := request.URL.Path[len("/list/"):]
	file, err := os.Open(path)
	if err != nil {
		return err
	}
	defer file.Close()

	all, err := ioutil.ReadAll(file)

	if err != nil {
		return err
	}

	writer.Write(all)
	return nil
}

type appHandler func(writer http.ResponseWriter, request *http.Request) error

func errWrapper(handler appHandler) func(w http.ResponseWriter, r *http.Request) {
	return func(w http.ResponseWriter, r *http.Request) {
		err := handler(w, r)
		if err != nil {
			code := http.StatusOK
			switch {
			case os.IsNotExist(err):
				code = http.StatusNotFound
			default:
				code = http.StatusInternalServerError
			}
			http.Error(w, http.StatusText(code), code)
		}
	}
}
```

当有错误出现的时候，我们将错误返回，而不是直接处理错误。我们通过`errWrapper`封装一个统一处理错误的方法。

# 0x03 panic

不要经常使用`panic`，`panic`的作用和其他语言中的`throw`类似

- 停止当前函数执行
- 一直向上返回，执行每一层的`defer`
- 如果没有遇到`recover`，程序退出

`recover`的作用相当于捕获异常

```go
func tryRecover() {
	defer func() {
		r := recover()
		if err, ok := r.(error); ok {
			fmt.Println("Error occurred:", err)
		} else {
			panic(r)
		}
	}()

	panic(errors.New("this is an error"))
}
```

